Workbook

Sheet Overview
B2: Cross-Use Case Matrix (Weighted AveAgentice out of 5) | M2: Cross-Use Case Matrix (Average: Avg) | W2: Cross-Use Case Matrix (Average: StdDev)
B3: Use Case | C3: OpenAI | E3: Gemini | M3: Use Case | N3: OpenAI | Q3: Gemini | W3: Use Case | X3: OpenAI | AA3: Gemini
C4: Agentic | D4: Agentic | E4: Agentic | F4: Agentic | N4: RAG | O4: Agentic | P4: Total | Q4: RAG | R4: Agentic | S4: Total | T4: RAG Total | U4: Agentic Total | X4: RAG | Y4: Agentic | Z4: Total | AA4: RAG | AB4: Agentic | AC4: Total | AD4: RAG Total | AE4: Agentic Total
B5: Gifts & Entertainment | C5: ='OAI Agentic G+E'!I27 -> 3.721 | D5: ='OAI Agentic G+E'!I27 -> 3.721 | E5: ='Gemini Agentic G+E'!I27 -> 3.7368 | F5: ='Gemini Agentic G+E'!I27 -> 3.7368 | M5: Factual Acc | N5: =AVERAGE(D17,J17,P17,V17,AB17,AH17) -> 4.24 | O5: =AVERAGE(D35,J35,P35) -> 2.9928205 | P5: =AVERAGE(N5:O5) -> 3.6164103 | Q5: =AVERAGE(D26,J26,P26,V26,AB26,AH26) -> 4.4199821 | R5: =AVERAGE(D44,J44,P44) -> 3.8005128 | S5: =AVERAGE(Q5:R5) -> 4.1102475 | T5: =AVERAGE(Q5,N5) -> 4.3299911 | U5: =AVERAGE(R5,O5) -> 3.3966667 | W5: Factual Acc | X5: =AVERAGE(F17,L17,R17,X17,AD17,AJ17) -> 0.9188222 | Y5: =AVERAGE(F35,L35,R35) -> 0.82655426 | Z5: =AVERAGE(X5:Y5) -> 0.87268823 | AA5: =AVERAGE(F26,L26,R26,X26,AD26,AJ26) -> 0.78153684 | AB5: =AVERAGE(F44,L44,R44) -> 0.76846057 | AC5: =AVERAGE(AA5:AB5) -> 0.7749987 | AD5: =AVERAGE(AA5,X5) -> 0.85017952 | AE5: =AVERAGE(AB5,Y5) -> 0.79750742
B6: IT-Governance | C6: ='OAI Agentic IT-G'!I27 -> 3.3865 | D6: ='OAI Agentic IT-G'!I27 -> 3.3865 | E6: ='Gemini Agentic IT-G'!I27 -> 3.3312 | F6: ='Gemini Agentic IT-G'!I27 -> 3.3312 | M6: Relevance | N6: =AVERAGE(D18,J18,P18,V18,AB18,AH18) -> 4.7105128 | O6: =AVERAGE(D36,J36,P36) -> 3.9461538 | P6: =AVERAGE(N6:O6) -> 4.3283333 | Q6: =AVERAGE(D27,J27,P27,V27,AB27,AH27) -> 4.6677957 | R6: =AVERAGE(D45,J45,P45) -> 4.3328205 | S6: =AVERAGE(Q6:R6) -> 4.5003081 | T6: =AVERAGE(Q6,N6) -> 4.6891542 | U6: =AVERAGE(R6,O6) -> 4.1394872 | W6: Relevance | X6: =AVERAGE(F18,L18,R18,X18,AD18,AJ18) -> 0.72390257 | Y6: =AVERAGE(F36,L36,R36) -> 0.64216813 | Z6: =AVERAGE(X6:Y6) -> 0.68303535 | AA6: =AVERAGE(F27,L27,R27,X27,AD27,AJ27) -> 0.8251987 | AB6: =AVERAGE(F45,L45,R45) -> 0.72749219 | AC6: =AVERAGE(AA6:AB6) -> 0.77634545 | AD6: =AVERAGE(AA6,X6) -> 0.77455064 | AE6: =AVERAGE(AB6,Y6) -> 0.68483016
B7: New HQ v0 | C7: ='OAI RAG NHQ v0'!I131 -> 5 | D7: ='OAI Agentic NHQ'!I132 -> 2.6642308 | E7: ='Gemini RAG NHQ v0'!I132 -> 3.7521538 | F7: ='Gemini Agentic NHQ'!I132 -> 4.052 | M7: Completeness | N7: =AVERAGE(D19,J19,P19,V19,AB19,AH19) -> 3.8871795 | O7: =AVERAGE(D37,J37,P37) -> 2.9061538 | P7: =AVERAGE(N7:O7) -> 3.3966667 | Q7: =AVERAGE(D28,J28,P28,V28,AB28,AH28) -> 3.8959273 | R7: =AVERAGE(D46,J46,P46) -> 3.2948718 | S7: =AVERAGE(Q7:R7) -> 3.5953995 | T7: =AVERAGE(Q7,N7) -> 3.8915534 | U7: =AVERAGE(R7,O7) -> 3.1005128 | W7: Completeness | X7: =AVERAGE(F19,L19,R19,X19,AD19,AJ19) -> 0.84961744 | Y7: =AVERAGE(F37,L37,R37) -> 0.78243232 | Z7: =AVERAGE(X7:Y7) -> 0.81602488 | AA7: =AVERAGE(F28,L28,R28,X28,AD28,AJ28) -> 0.94834778 | AB7: =AVERAGE(F46,L46,R46) -> 0.90802778 | AC7: =AVERAGE(AA7:AB7) -> 0.92818778 | AD7: =AVERAGE(AA7,X7) -> 0.89898261 | AE7: =AVERAGE(AB7,Y7) -> 0.84523005
B8: New HQ v1 | C8: ='OAI RAG NHQ v1'!I132 -> 4.2584615 | E8: ='Gemini RAG NHQ v1'!I131 -> 3.8651163 | M8: Clarity | N8: =AVERAGE(D20,J20,P20,V20,AB20,AH20) -> 4.5233333 | O8: =AVERAGE(D38,J38,P38) -> 3.8307692 | P8: =AVERAGE(N8:O8) -> 4.1770513 | Q8: =AVERAGE(D29,J29,P29,V29,AB29,AH29) -> 4.6448678 | R8: =AVERAGE(D47,J47,P47) -> 4.4010256 | S8: =AVERAGE(Q8:R8) -> 4.5229467 | T8: =AVERAGE(Q8,N8) -> 4.5841006 | U8: =AVERAGE(R8,O8) -> 4.1158974 | W8: Clarity | X8: =AVERAGE(F20,L20,R20,X20,AD20,AJ20) -> 0.65391126 | Y8: =AVERAGE(F38,L38,R38) -> 0.6297461 | Z8: =AVERAGE(X8:Y8) -> 0.64182868 | AA8: =AVERAGE(F29,L29,R29,X29,AD29,AJ29) -> 0.75315685 | AB8: =AVERAGE(F47,L47,R47) -> 0.53213719 | AC8: =AVERAGE(AA8:AB8) -> 0.64264702 | AD8: =AVERAGE(AA8,X8) -> 0.70353406 | AE8: =AVERAGE(AB8,Y8) -> 0.58094165
B9: New HQ v2 | C9: ='OAI RAG NHQ v2'!I132 -> 4.1578846 | E9: ='Gemini RAG NHQ v2'!I132 -> 3.8461538 | M9: Citation Q. | N9: =AVERAGE(D21,J21,P21,V21,AB21,AH21) -> 3.2866667 | O9: =AVERAGE(D39,J39,P39) -> 1.9205128 | P9: =AVERAGE(N9:O9) -> 2.6035897 | Q9: =AVERAGE(D30,J30,P30,V30,AB30,AH30) -> 1.3682906 | R9: =AVERAGE(D48,J48,P48) -> 2.3605128 | S9: =AVERAGE(Q9:R9) -> 1.8644017 | T9: =AVERAGE(Q9,N9) -> 2.3274786 | U9: =AVERAGE(R9,O9) -> 2.1405128 | W9: Citation Q. | X9: =AVERAGE(F21,L21,R21,X21,AD21,AJ21) -> 0.91574173 | Y9: =AVERAGE(F39,L39,R39) -> 0.63586976 | Z9: =AVERAGE(X9:Y9) -> 0.77580574 | AA9: =AVERAGE(F30,L30,R30,X30,AD30,AJ30) -> 0.71937447 | AB9: =AVERAGE(F48,L48,R48) -> 0.85567967 | AC9: =AVERAGE(AA9:AB9) -> 0.78752707 | AD9: =AVERAGE(AA9,X9) -> 0.8175581 | AE9: =AVERAGE(AB9,Y9) -> 0.74577471
B10: New HQ v3 | C10: ='OAI RAG NHQ v3'!I132 -> 4.5844231 | E10: ='Gemini RAG NHQ v3'!I131 -> 4.0421705 | M10: Raw Total | N10: =AVERAGE(D22,J22,P22,V22,AB22,AH22) -> 20.647692 | O10: =AVERAGE(D40,J40,P40) -> 15.59641 | P10: =AVERAGE(N10:O10) -> 18.122051 | Q10: =AVERAGE(D31,J31,P31,V31,AB31,AH31) -> 18.996863 | R10: =AVERAGE(D49,J49,P49) -> 18.189744 | S10: =AVERAGE(Q10:R10) -> 18.593304 | T10: =AVERAGE(Q10,N10) -> 19.822278 | U10: =AVERAGE(R10,O10) -> 16.893077 | W10: Raw Total | X10: =AVERAGE(F22,L22,R22,X22,AD22,AJ22) -> 3.6712839 | Y10: =AVERAGE(F40,L40,R40) -> 3.1250289 | Z10: =AVERAGE(X10:Y10) -> 3.3981564 | AA10: =AVERAGE(F31,L31,R31,X31,AD31,AJ31) -> 3.241983 | AB10: =AVERAGE(F49,L49,R49) -> 2.9212235 | AC10: =AVERAGE(AA10:AB10) -> 3.0816032 | AD10: =AVERAGE(AA10,X10) -> 3.4566334 | AE10: =AVERAGE(AB10,Y10) -> 3.0231262
B11: TOTAL AVG | C11: =AVERAGE(C5:C10) -> 4.1847115 | D11: =AVERAGE(D5:D10) -> 3.2572436 | E11: =AVERAGE(E5:E10) -> 3.7622658 | F11: =AVERAGE(F5:F10) -> 3.7066667
B12: gemini vs openai | C12: =(C11-E11)/C11 -> 0.1009498 | D12: =(D11-F11)/D11 -> -0.1379765 | E12: =(E11-C11)/C11 -> -0.1009498 | F12: =(F11-D11)/D11 -> 0.1379765
B15: Gifts & Entertainment: OpenAI RAG Performance | H15: IT-Governance: OpenAI RAG Performance | N15: New HQ v0: OpenAI RAG Performance | T15: New HQ v1: OpenAI RAG Performance | Z15: New HQ v2: OpenAI RAG Performance | AF15: New HQ v3: OpenAI RAG Performance
B16: Metric | C16: Min | D16: AVG | E16: Max | F16: StdDev | H16: Metric | I16: Min | J16: AVG | K16: Max | L16: StdDev | N16: Metric | O16: Min | P16: AVG | Q16: Max | R16: StdDev | T16: Metric | U16: Min | V16: AVG | W16: Max | X16: StdDev | Z16: Metric | AA16: Min | AB16: AVG | AC16: Max | AD16: StdDev | AF16: Metric | AG16: Min | AH16: AVG | AI16: Max | AJ16: StdDev
B17: Factual Acc | C17: =MIN('OAI RAG G+E'!D:D) -> 3 | D17: =AVERAGE('OAI RAG G+E'!D:D) -> 4.36 | E17: =MAX('OAI RAG G+E'!D:D) -> 5 | F17: =_xlfn.STDEV.S('OAI RAG G+E'!D2:D26) -> 0.56862407 | H17: Factual Acc | I17: =MIN('OAI RAG IT-G'!D:D) -> 3 | J17: =AVERAGE('OAI RAG IT-G'!D:D) -> 4.28 | K17: =MAX('OAI RAG IT-G'!D:D) -> 5 | L17: =_xlfn.STDEV.S('OAI RAG IT-G'!D2:D26) -> 0.61373175 | N17: Factual Acc | O17: =MIN('OAI RAG NHQ v0'!D:D) -> 1 | P17: =AVERAGE('OAI RAG NHQ v0'!D:D) -> 3.6846154 | Q17: =MAX('OAI RAG NHQ v0'!D:D) -> 5 | R17: =_xlfn.STDEV.S('OAI RAG NHQ v0'!D2:D131) -> 1.4575897 | T17: Factual Acc | U17: =MIN('OAI RAG NHQ v1'!D:D) -> 1 | V17: =AVERAGE('OAI RAG NHQ v1'!D:D) -> 4.2769231 | W17: =MAX('OAI RAG NHQ v1'!D:D) -> 5 | X17: =_xlfn.STDEV.S('OAI RAG NHQ v1'!D2:D131) -> 1.0039873 | Z17: Factual Acc | AA17: =MIN('OAI RAG NHQ v2'!D:D) -> 1 | AB17: =AVERAGE('OAI RAG NHQ v2'!D:D) -> 4.1384615 | AC17: =MAX('OAI RAG NHQ v2'!D:D) -> 5 | AD17: =_xlfn.STDEV.S('OAI RAG NHQ v2'!D2:D131) -> 1.1049841 | AF17: Factual Acc | AG17: =MIN('OAI RAG NHQ v3'!D:D) -> 1 | AH17: =AVERAGE('OAI RAG NHQ v3'!D:D) -> 4.7 | AI17: =MAX('OAI RAG NHQ v3'!D:D) -> 5 | AJ17: =_xlfn.STDEV.S('OAI RAG NHQ v3'!D2:D131) -> 0.76401632
B18: Relevance | C18: =MIN('OAI RAG G+E'!E:E) -> 4 | D18: =AVERAGE('OAI RAG G+E'!E:E) -> 4.96 | E18: =MAX('OAI RAG G+E'!E:E) -> 5 | F18: =_xlfn.STDEV.S('OAI RAG G+E'!E2:E26) -> 0.2 | H18: Relevance | I18: =MIN('OAI RAG IT-G'!E:E) -> 3 | J18: =AVERAGE('OAI RAG IT-G'!E:E) -> 4.88 | K18: =MAX('OAI RAG IT-G'!E:E) -> 5 | L18: =_xlfn.STDEV.S('OAI RAG IT-G'!E2:E26) -> 0.43969687 | N18: Relevance | O18: =MIN('OAI RAG NHQ v0'!E:E) -> 1 | P18: =AVERAGE('OAI RAG NHQ v0'!E:E) -> 4.2461538 | Q18: =MAX('OAI RAG NHQ v0'!E:E) -> 5 | R18: =_xlfn.STDEV.S('OAI RAG NHQ v0'!E2:E131) -> 1.3414185 | T18: Relevance | U18: =MIN('OAI RAG NHQ v1'!E:E) -> 1 | V18: =AVERAGE('OAI RAG NHQ v1'!E:E) -> 4.7076923 | W18: =MAX('OAI RAG NHQ v1'!E:E) -> 5 | X18: =_xlfn.STDEV.S('OAI RAG NHQ v1'!E2:E131) -> 0.76194522 | Z18: Relevance | AA18: =MIN('OAI RAG NHQ v2'!E:E) -> 1 | AB18: =AVERAGE('OAI RAG NHQ v2'!E:E) -> 4.6076923 | AC18: =MAX('OAI RAG NHQ v2'!E:E) -> 5 | AD18: =_xlfn.STDEV.S('OAI RAG NHQ v2'!E2:E131) -> 0.96846521 | AF18: Relevance | AG18: =MIN('OAI RAG NHQ v3'!E:E) -> 1 | AH18: =AVERAGE('OAI RAG NHQ v3'!E:E) -> 4.8615385 | AI18: =MAX('OAI RAG NHQ v3'!E:E) -> 5 | AJ18: =_xlfn.STDEV.S('OAI RAG NHQ v3'!E2:E131) -> 0.63188958
B19: Completeness | C19: =MIN('OAI RAG G+E'!F:F) -> 3 | D19: =AVERAGE('OAI RAG G+E'!F:F) -> 4.28 | E19: =MAX('OAI RAG G+E'!F:F) -> 5 | F19: =_xlfn.STDEV.S('OAI RAG G+E'!F2:F26) -> 0.54160256 | H19: Completeness | I19: =MIN('OAI RAG IT-G'!F:F) -> 2 | J19: =AVERAGE('OAI RAG IT-G'!F:F) -> 4.12 | K19: =MAX('OAI RAG IT-G'!F:F) -> 5 | L19: =_xlfn.STDEV.S('OAI RAG IT-G'!F2:F26) -> 0.66583281 | N19: Completeness | O19: =MIN('OAI RAG NHQ v0'!F:F) -> 1 | P19: =AVERAGE('OAI RAG NHQ v0'!F:F) -> 3.2692308 | Q19: =MAX('OAI RAG NHQ v0'!F:F) -> 5 | R19: =_xlfn.STDEV.S('OAI RAG NHQ v0'!F2:F131) -> 1.2313002 | T19: Completeness | U19: =MIN('OAI RAG NHQ v1'!F:F) -> 1 | V19: =AVERAGE('OAI RAG NHQ v1'!F:F) -> 3.7923077 | W19: =MAX('OAI RAG NHQ v1'!F:F) -> 5 | X19: =_xlfn.STDEV.S('OAI RAG NHQ v1'!F2:F131) -> 0.85992747 | Z19: Completeness | AA19: =MIN('OAI RAG NHQ v2'!F:F) -> 1 | AB19: =AVERAGE('OAI RAG NHQ v2'!F:F) -> 3.7307692 | AC19: =MAX('OAI RAG NHQ v2'!F:F) -> 5 | AD19: =_xlfn.STDEV.S('OAI RAG NHQ v2'!F2:F131) -> 1.0175854 | AF19: Completeness | AG19: =MIN('OAI RAG NHQ v3'!F:F) -> 1 | AH19: =AVERAGE('OAI RAG NHQ v3'!F:F) -> 4.1307692 | AI19: =MAX('OAI RAG NHQ v3'!F:F) -> 5 | AJ19: =_xlfn.STDEV.S('OAI RAG NHQ v3'!F2:F131) -> 0.78145622
B20: Clarity | C20: =MIN('OAI RAG G+E'!G:G) -> 4 | D20: =AVERAGE('OAI RAG G+E'!G:G) -> 4.44 | E20: =MAX('OAI RAG G+E'!G:G) -> 5 | F20: =_xlfn.STDEV.S('OAI RAG G+E'!G2:G26) -> 0.50662281 | H20: Clarity | I20: =MIN('OAI RAG IT-G'!G:G) -> 4 | J20: =AVERAGE('OAI RAG IT-G'!G:G) -> 4.4 | K20: =MAX('OAI RAG IT-G'!G:G) -> 5 | L20: =_xlfn.STDEV.S('OAI RAG IT-G'!G2:G26) -> 0.5 | N20: Clarity | O20: =MIN('OAI RAG NHQ v0'!G:G) -> 2 | P20: =AVERAGE('OAI RAG NHQ v0'!G:G) -> 4.3538462 | Q20: =MAX('OAI RAG NHQ v0'!G:G) -> 5 | R20: =_xlfn.STDEV.S('OAI RAG NHQ v0'!G2:G131) -> 0.95529157 | T20: Clarity | U20: =MIN('OAI RAG NHQ v1'!G:G) -> 1 | V20: =AVERAGE('OAI RAG NHQ v1'!G:G) -> 4.6230769 | W20: =MAX('OAI RAG NHQ v1'!G:G) -> 5 | X20: =_xlfn.STDEV.S('OAI RAG NHQ v1'!G2:G131) -> 0.66198415 | Z20: Clarity | AA20: =MIN('OAI RAG NHQ v2'!G:G) -> 2 | AB20: =AVERAGE('OAI RAG NHQ v2'!G:G) -> 4.5076923 | AC20: =MAX('OAI RAG NHQ v2'!G:G) -> 5 | AD20: =_xlfn.STDEV.S('OAI RAG NHQ v2'!G2:G131) -> 0.75990772 | AF20: Clarity | AG20: =MIN('OAI RAG NHQ v3'!G:G) -> 2 | AH20: =AVERAGE('OAI RAG NHQ v3'!G:G) -> 4.8153846 | AI20: =MAX('OAI RAG NHQ v3'!G:G) -> 5 | AJ20: =_xlfn.STDEV.S('OAI RAG NHQ v3'!G2:G131) -> 0.53966133
B21: Citation Q. | C21: =MIN('OAI RAG G+E'!H:H) -> 2 | D21: =AVERAGE('OAI RAG G+E'!H:H) -> 3.32 | E21: =MAX('OAI RAG G+E'!H:H) -> 4 | F21: =_xlfn.STDEV.S('OAI RAG G+E'!H2:H26) -> 0.62716292 | H21: Citation Q. | I21: =MIN('OAI RAG IT-G'!H:H) -> 2 | J21: =AVERAGE('OAI RAG IT-G'!H:H) -> 3.2 | K21: =MAX('OAI RAG IT-G'!H:H) -> 4 | L21: =_xlfn.STDEV.S('OAI RAG IT-G'!H2:H26) -> 0.64549722 | N21: Citation Q. | O21: =MIN('OAI RAG NHQ v0'!H:H) -> 1 | P21: =AVERAGE('OAI RAG NHQ v0'!H:H) -> 2.8384615 | Q21: =MAX('OAI RAG NHQ v0'!H:H) -> 5 | R21: =_xlfn.STDEV.S('OAI RAG NHQ v0'!H2:H131) -> 1.2563257 | T21: Citation Q. | U21: =MIN('OAI RAG NHQ v1'!H:H) -> 1 | V21: =AVERAGE('OAI RAG NHQ v1'!H:H) -> 3.2307692 | W21: =MAX('OAI RAG NHQ v1'!H:H) -> 5 | X21: =_xlfn.STDEV.S('OAI RAG NHQ v1'!H2:H131) -> 0.92793395 | Z21: Citation Q. | AA21: =MIN('OAI RAG NHQ v2'!H:H) -> 1 | AB21: =AVERAGE('OAI RAG NHQ v2'!H:H) -> 3.2076923 | AC21: =MAX('OAI RAG NHQ v2'!H:H) -> 5 | AD21: =_xlfn.STDEV.S('OAI RAG NHQ v2'!H2:H131) -> 1.0761412 | AF21: Citation Q. | AG21: =MIN('OAI RAG NHQ v3'!H:H) -> 1 | AH21: =AVERAGE('OAI RAG NHQ v3'!H:H) -> 3.9230769 | AI21: =MAX('OAI RAG NHQ v3'!H:H) -> 5 | AJ21: =_xlfn.STDEV.S('OAI RAG NHQ v3'!H2:H131) -> 0.96138937
B22: Overall Score | C22: =MIN('OAI RAG G+E'!J:J) -> 16 | D22: =AVERAGE('OAI RAG G+E'!J:J) -> 21.36 | E22: =MAX('OAI RAG G+E'!J:J) -> 24 | F22: =_xlfn.STDEV.S('OAI RAG G+E'!J2:J26) -> 2.0792627 | H22: Overall Score | I22: =MIN('OAI RAG IT-G'!J:J) -> 15 | J22: =AVERAGE('OAI RAG IT-G'!J:J) -> 20.88 | K22: =MAX('OAI RAG IT-G'!J:J) -> 24 | L22: =_xlfn.STDEV.S('OAI RAG IT-G'!J2:J26) -> 2.2420229 | N22: Overall Score | O22: =MIN('OAI RAG NHQ v0'!J:J) -> 6 | P22: =AVERAGE('OAI RAG NHQ v0'!J:J) -> 18.392308 | Q22: =MAX('OAI RAG NHQ v0'!J:J) -> 25 | R22: =_xlfn.STDEV.S('OAI RAG NHQ v0'!J2:J131) -> 5.8832256 | T22: Overall Score | U22: =MIN('OAI RAG NHQ v1'!J:J) -> 5 | V22: =AVERAGE('OAI RAG NHQ v1'!J:J) -> 20.630769 | W22: =MAX('OAI RAG NHQ v1'!J:J) -> 25 | X22: =_xlfn.STDEV.S('OAI RAG NHQ v1'!J2:J131) -> 3.9140741 | Z22: Overall Score | AA22: =MIN('OAI RAG NHQ v2'!J:J) -> 6 | AB22: =AVERAGE('OAI RAG NHQ v2'!J:J) -> 20.192308 | AC22: =MAX('OAI RAG NHQ v2'!J:J) -> 25 | AD22: =_xlfn.STDEV.S('OAI RAG NHQ v2'!J2:J131) -> 4.6055177 | AF22: Overall Score | AG22: =MIN('OAI RAG NHQ v3'!J:J) -> 6 | AH22: =AVERAGE('OAI RAG NHQ v3'!J:J) -> 22.430769 | AI22: =MAX('OAI RAG NHQ v3'!J:J) -> 25 | AJ22: =_xlfn.STDEV.S('OAI RAG NHQ v3'!J2:J131) -> 3.3036002
B24: Gifts & Entertainment: Gemini RAG Performance | H24: IT-Governance: Gemini RAG Performance | N24: New HQ v0: Gemini RAG Performance | T24: New HQ v1: Gemini RAG Performance | Z24: New HQ v2: Gemini RAG Performance | AF24: New HQ v3: Gemini RAG Performance
B25: Metric | C25: Min | D25: AVG | E25: Max | F25: StdDev | H25: Metric | I25: Min | J25: AVG | K25: Max | L25: StdDev | N25: Metric | O25: Min | P25: AVG | Q25: Max | R25: StdDev | T25: Metric | U25: Min | V25: AVG | W25: Max | X25: StdDev | Z25: Metric | AA25: Min | AB25: AVG | AC25: Max | AD25: StdDev | AF25: Metric | AG25: Min | AH25: AVG | AI25: Max | AJ25: StdDev
B26: Factual Acc | C26: =MIN('Gemini RAG G+E'!D:D) -> 4 | D26: =AVERAGE('Gemini RAG G+E'!D:D) -> 4.48 | E26: =MAX('Gemini RAG G+E'!D:D) -> 5 | F26: =_xlfn.STDEV.S('Gemini RAG G+E'!D2:D26) -> 0.50990195 | H26: Factual Acc | I26: =MIN('Gemini RAG IT-G'!D:D) -> 2 | J26: =AVERAGE('Gemini RAG IT-G'!D:D) -> 4.2 | K26: =MAX('Gemini RAG IT-G'!D:D) -> 5 | L26: =_xlfn.STDEV.S('Gemini RAG IT-G'!D2:D26) -> 0.70710678 | N26: Factual Acc | O26: =MIN('Gemini RAG NHQ v0'!D:D) -> 1 | P26: =AVERAGE('Gemini RAG NHQ v0'!D:D) -> 4.2307692 | Q26: =MAX('Gemini RAG NHQ v0'!D:D) -> 5 | R26: =_xlfn.STDEV.S('Gemini RAG NHQ v0'!D2:D131) -> 1.1782161 | T26: Factual Acc | U26: =MIN('Gemini RAG NHQ v1'!D:D) -> 1 | V26: =AVERAGE('Gemini RAG NHQ v1'!D:D) -> 4.4108527 | W26: =MAX('Gemini RAG NHQ v1'!D:D) -> 5 | X26: =_xlfn.STDEV.S('Gemini RAG NHQ v1'!D2:D130) -> 0.83490646 | Z26: Factual Acc | AA26: =MIN('Gemini RAG NHQ v2'!D:D) -> 1 | AB26: =AVERAGE('Gemini RAG NHQ v2'!D:D) -> 4.4230769 | AC26: =MAX('Gemini RAG NHQ v2'!D:D) -> 5 | AD26: =_xlfn.STDEV.S('Gemini RAG NHQ v2'!D2:D131) -> 0.89672431 | AF26: Factual Acc | AG26: =MIN('Gemini RAG NHQ v3'!D:D) -> 1 | AH26: =AVERAGE('Gemini RAG NHQ v3'!D:D) -> 4.7751938 | AI26: =MAX('Gemini RAG NHQ v3'!D:D) -> 5 | AJ26: =_xlfn.STDEV.S('Gemini RAG NHQ v3'!D2:D130) -> 0.5623654
B27: Relevance | C27: =MIN('Gemini RAG G+E'!E:E) -> 4 | D27: =AVERAGE('Gemini RAG G+E'!E:E) -> 4.96 | E27: =MAX('Gemini RAG G+E'!E:E) -> 5 | F27: =_xlfn.STDEV.S('Gemini RAG G+E'!E2:E26) -> 0.2 | H27: Relevance | I27: =MIN('Gemini RAG IT-G'!E:E) -> 1 | J27: =AVERAGE('Gemini RAG IT-G'!E:E) -> 4.72 | K27: =MAX('Gemini RAG IT-G'!E:E) -> 5 | L27: =_xlfn.STDEV.S('Gemini RAG IT-G'!E2:E26) -> 0.84261498 | N27: Relevance | O27: =MIN('Gemini RAG NHQ v0'!E:E) -> 1 | P27: =AVERAGE('Gemini RAG NHQ v0'!E:E) -> 4.2461538 | Q27: =MAX('Gemini RAG NHQ v0'!E:E) -> 5 | R27: =_xlfn.STDEV.S('Gemini RAG NHQ v0'!E2:E131) -> 1.4200204 | T27: Relevance | U27: =MIN('Gemini RAG NHQ v1'!E:E) -> 1 | V27: =AVERAGE('Gemini RAG NHQ v1'!E:E) -> 4.6356589 | W27: =MAX('Gemini RAG NHQ v1'!E:E) -> 5 | X27: =_xlfn.STDEV.S('Gemini RAG NHQ v1'!E2:E130) -> 0.85639127 | Z27: Relevance | AA27: =MIN('Gemini RAG NHQ v2'!E:E) -> 1 | AB27: =AVERAGE('Gemini RAG NHQ v2'!E:E) -> 4.6 | AC27: =MAX('Gemini RAG NHQ v2'!E:E) -> 5 | AD27: =_xlfn.STDEV.S('Gemini RAG NHQ v2'!E2:E131) -> 0.97726085 | AF27: Relevance | AG27: =MIN('Gemini RAG NHQ v3'!E:E) -> 1 | AH27: =AVERAGE('Gemini RAG NHQ v3'!E:E) -> 4.8449612 | AI27: =MAX('Gemini RAG NHQ v3'!E:E) -> 5 | AJ27: =_xlfn.STDEV.S('Gemini RAG NHQ v3'!E2:E130) -> 0.65490472
B28: Completeness | C28: =MIN('Gemini RAG G+E'!F:F) -> 3 | D28: =AVERAGE('Gemini RAG G+E'!F:F) -> 4.2 | E28: =MAX('Gemini RAG G+E'!F:F) -> 5 | F28: =_xlfn.STDEV.S('Gemini RAG G+E'!F2:F26) -> 0.5 | H28: Completeness | I28: =MIN('Gemini RAG IT-G'!F:F) -> 1 | J28: =AVERAGE('Gemini RAG IT-G'!F:F) -> 3.76 | K28: =MAX('Gemini RAG IT-G'!F:F) -> 5 | L28: =_xlfn.STDEV.S('Gemini RAG IT-G'!F2:F26) -> 0.83066239 | N28: Completeness | O28: =MIN('Gemini RAG NHQ v0'!F:F) -> 1 | P28: =AVERAGE('Gemini RAG NHQ v0'!F:F) -> 3.5384615 | Q28: =MAX('Gemini RAG NHQ v0'!F:F) -> 5 | R28: =_xlfn.STDEV.S('Gemini RAG NHQ v0'!F2:F131) -> 1.3985255 | T28: Completeness | U28: =MIN('Gemini RAG NHQ v1'!F:F) -> 1 | V28: =AVERAGE('Gemini RAG NHQ v1'!F:F) -> 3.7984496 | W28: =MAX('Gemini RAG NHQ v1'!F:F) -> 5 | X28: =_xlfn.STDEV.S('Gemini RAG NHQ v1'!F2:F130) -> 0.97130586 | Z28: Completeness | AA28: =MIN('Gemini RAG NHQ v2'!F:F) -> 1 | AB28: =AVERAGE('Gemini RAG NHQ v2'!F:F) -> 3.8538462 | AC28: =MAX('Gemini RAG NHQ v2'!F:F) -> 5 | AD28: =_xlfn.STDEV.S('Gemini RAG NHQ v2'!F2:F131) -> 1.1214024 | AF28: Completeness | AG28: =MIN('Gemini RAG NHQ v3'!F:F) -> 1 | AH28: =AVERAGE('Gemini RAG NHQ v3'!F:F) -> 4.2248062 | AI28: =MAX('Gemini RAG NHQ v3'!F:F) -> 5 | AJ28: =_xlfn.STDEV.S('Gemini RAG NHQ v3'!F2:F130) -> 0.86819056
B29: Clarity | C29: =MIN('Gemini RAG G+E'!G:G) -> 4 | D29: =AVERAGE('Gemini RAG G+E'!G:G) -> 4.68 | E29: =MAX('Gemini RAG G+E'!G:G) -> 5 | F29: =_xlfn.STDEV.S('Gemini RAG G+E'!G2:G26) -> 0.47609523 | H29: Clarity | I29: =MIN('Gemini RAG IT-G'!G:G) -> 3 | J29: =AVERAGE('Gemini RAG IT-G'!G:G) -> 4.4 | K29: =MAX('Gemini RAG IT-G'!G:G) -> 5 | L29: =_xlfn.STDEV.S('Gemini RAG IT-G'!G2:G26) -> 0.57735027 | N29: Clarity | O29: =MIN('Gemini RAG NHQ v0'!G:G) -> 1 | P29: =AVERAGE('Gemini RAG NHQ v0'!G:G) -> 4.4923077 | Q29: =MAX('Gemini RAG NHQ v0'!G:G) -> 5 | R29: =_xlfn.STDEV.S('Gemini RAG NHQ v0'!G2:G131) -> 1.2590519 | T29: Clarity | U29: =MIN('Gemini RAG NHQ v1'!G:G) -> 1 | V29: =AVERAGE('Gemini RAG NHQ v1'!G:G) -> 4.7596899 | W29: =MAX('Gemini RAG NHQ v1'!G:G) -> 5 | X29: =_xlfn.STDEV.S('Gemini RAG NHQ v1'!G2:G130) -> 0.68208314 | Z29: Clarity | AA29: =MIN('Gemini RAG NHQ v2'!G:G) -> 1 | AB29: =AVERAGE('Gemini RAG NHQ v2'!G:G) -> 4.7 | AC29: =MAX('Gemini RAG NHQ v2'!G:G) -> 5 | AD29: =_xlfn.STDEV.S('Gemini RAG NHQ v2'!G2:G131) -> 0.87736392 | AF29: Clarity | AG29: =MIN('Gemini RAG NHQ v3'!G:G) -> 1 | AH29: =AVERAGE('Gemini RAG NHQ v3'!G:G) -> 4.8372093 | AI29: =MAX('Gemini RAG NHQ v3'!G:G) -> 5 | AJ29: =_xlfn.STDEV.S('Gemini RAG NHQ v3'!G2:G130) -> 0.64699664
B30: Citation Q. | C30: =MIN('Gemini RAG G+E'!H:H) -> 1 | D30: =AVERAGE('Gemini RAG G+E'!H:H) -> 1.8 | E30: =MAX('Gemini RAG G+E'!H:H) -> 4 | F30: =_xlfn.STDEV.S('Gemini RAG G+E'!H2:H26) -> 0.95742711 | H30: Citation Q. | I30: =MIN('Gemini RAG IT-G'!H:H) -> 1 | J30: =AVERAGE('Gemini RAG IT-G'!H:H) -> 1.52 | K30: =MAX('Gemini RAG IT-G'!H:H) -> 2 | L30: =_xlfn.STDEV.S('Gemini RAG IT-G'!H2:H26) -> 0.50990195 | N30: Citation Q. | O30: =MIN('Gemini RAG NHQ v0'!H:H) -> 1 | P30: =AVERAGE('Gemini RAG NHQ v0'!H:H) -> 1.1230769 | Q30: =MAX('Gemini RAG NHQ v0'!H:H) -> 5 | R30: =_xlfn.STDEV.S('Gemini RAG NHQ v0'!H2:H131) -> 0.57080637 | T30: Citation Q. | U30: =MIN('Gemini RAG NHQ v1'!H:H) -> 1 | V30: =AVERAGE('Gemini RAG NHQ v1'!H:H) -> 1.0775194 | W30: =MAX('Gemini RAG NHQ v1'!H:H) -> 3 | X30: =_xlfn.STDEV.S('Gemini RAG NHQ v1'!H2:H130) -> 0.3448823 | Z30: Citation Q. | AA30: =MIN('Gemini RAG NHQ v2'!H:H) -> 1 | AB30: =AVERAGE('Gemini RAG NHQ v2'!H:H) -> 1.1 | AC30: =MAX('Gemini RAG NHQ v2'!H:H) -> 5 | AD30: =_xlfn.STDEV.S('Gemini RAG NHQ v2'!H2:H131) -> 0.55475394 | AF30: Citation Q. | AG30: =MIN('Gemini RAG NHQ v3'!H:H) -> 1 | AH30: =AVERAGE('Gemini RAG NHQ v3'!H:H) -> 1.5891473 | AI30: =MAX('Gemini RAG NHQ v3'!H:H) -> 5 | AJ30: =_xlfn.STDEV.S('Gemini RAG NHQ v3'!H2:H130) -> 1.3784752
B31: Overall Score | C31: =MIN('Gemini RAG G+E'!J:J) -> 17 | D31: =AVERAGE('Gemini RAG G+E'!J:J) -> 20.12 | E31: =MAX('Gemini RAG G+E'!J:J) -> 23 | F31: =_xlfn.STDEV.S('Gemini RAG G+E'!J2:J26) -> 1.9 | H31: Overall Score | I31: =MIN('Gemini RAG IT-G'!J:J) -> 8 | J31: =AVERAGE('Gemini RAG IT-G'!J:J) -> 18.6 | K31: =MAX('Gemini RAG IT-G'!J:J) -> 21 | L31: =_xlfn.STDEV.S('Gemini RAG IT-G'!J2:J26) -> 2.7386128 | N31: Overall Score | O31: =MIN('Gemini RAG NHQ v0'!J:J) -> 5 | P31: =AVERAGE('Gemini RAG NHQ v0'!J:J) -> 17.630769 | Q31: =MAX('Gemini RAG NHQ v0'!J:J) -> 25 | R31: =_xlfn.STDEV.S('Gemini RAG NHQ v0'!J2:J131) -> 4.9323147 | T31: Overall Score | U31: =MIN('Gemini RAG NHQ v1'!J:J) -> 5 | V31: =AVERAGE('Gemini RAG NHQ v1'!J:J) -> 18.682171 | W31: =MAX('Gemini RAG NHQ v1'!J:J) -> 23 | X31: =_xlfn.STDEV.S('Gemini RAG NHQ v1'!J2:J130) -> 3.1023794 | Z31: Overall Score | AA31: =MIN('Gemini RAG NHQ v2'!J:J) -> 5 | AB31: =AVERAGE('Gemini RAG NHQ v2'!J:J) -> 18.676923 | AC31: =MAX('Gemini RAG NHQ v2'!J:J) -> 25 | AD31: =_xlfn.STDEV.S('Gemini RAG NHQ v2'!J2:J131) -> 3.7046281 | AF31: Overall Score | AG31: =MIN('Gemini RAG NHQ v3'!J:J) -> 5 | AH31: =AVERAGE('Gemini RAG NHQ v3'!J:J) -> 20.271318 | AI31: =MAX('Gemini RAG NHQ v3'!J:J) -> 25 | AJ31: =_xlfn.STDEV.S('Gemini RAG NHQ v3'!J2:J130) -> 3.0739631
B33: Gifts & Entertainment: OpenAI Agentic Performance | H33: IT-Governance: OpenAI Agentic Performance | N33: New HQ: OpenAI Agentic Performance
B34: Metric | C34: Min | D34: AVG | E34: Max | F34: StdDev | H34: Metric | I34: Min | J34: AVG | K34: Max | L34: StdDev | N34: Metric | O34: Min | P34: AVG | Q34: Max | R34: StdDev
B35: Factual Acc | C35: =MIN('OAI Agentic G+E'!D:D) -> 1 | D35: =AVERAGE('OAI Agentic G+E'!D:D) -> 3.56 | E35: =MAX('OAI Agentic G+E'!D:D) -> 5 | F35: =_xlfn.STDEV.S('OAI RAG G+E'!D2:D26) -> 0.56862407 | H35: Factual Acc | I35: =MIN('OAI Agentic IT-G'!D:D) -> 1 | J35: =AVERAGE('OAI Agentic IT-G'!D:D) -> 3.08 | K35: =MAX('OAI Agentic IT-G'!D:D) -> 4 | L35: =_xlfn.STDEV.S('OAI RAG IT-G'!D2:D26) -> 0.61373175 | N35: Factual Acc | O35: =MIN('OAI Agentic NHQ'!D:D) -> 1 | P35: =AVERAGE('OAI Agentic NHQ'!D:D) -> 2.3384615 | Q35: =MAX('OAI Agentic NHQ'!D:D) -> 5 | R35: =_xlfn.STDEV.S('OAI Agentic NHQ'!D2:D131) -> 1.297307
B36: Relevance | C36: =MIN('OAI Agentic G+E'!E:E) -> 1 | D36: =AVERAGE('OAI Agentic G+E'!E:E) -> 4.52 | E36: =MAX('OAI Agentic G+E'!E:E) -> 5 | F36: =_xlfn.STDEV.S('OAI RAG G+E'!E2:E26) -> 0.2 | H36: Relevance | I36: =MIN('OAI Agentic IT-G'!E:E) -> 1 | J36: =AVERAGE('OAI Agentic IT-G'!E:E) -> 4.08 | K36: =MAX('OAI Agentic IT-G'!E:E) -> 5 | L36: =_xlfn.STDEV.S('OAI RAG IT-G'!E2:E26) -> 0.43969687 | N36: Relevance | O36: =MIN('OAI Agentic NHQ'!E:E) -> 1 | P36: =AVERAGE('OAI Agentic NHQ'!E:E) -> 3.2384615 | Q36: =MAX('OAI Agentic NHQ'!E:E) -> 5 | R36: =_xlfn.STDEV.S('OAI Agentic NHQ'!E2:E131) -> 1.2868075
B37: Completeness | C37: =MIN('OAI Agentic G+E'!F:F) -> 1 | D37: =AVERAGE('OAI Agentic G+E'!F:F) -> 3.32 | E37: =MAX('OAI Agentic G+E'!F:F) -> 4 | F37: =_xlfn.STDEV.S('OAI RAG G+E'!F2:F26) -> 0.54160256 | H37: Completeness | I37: =MIN('OAI Agentic IT-G'!F:F) -> 1 | J37: =AVERAGE('OAI Agentic IT-G'!F:F) -> 3.16 | K37: =MAX('OAI Agentic IT-G'!F:F) -> 4 | L37: =_xlfn.STDEV.S('OAI RAG IT-G'!F2:F26) -> 0.66583281 | N37: Completeness | O37: =MIN('OAI Agentic NHQ'!F:F) -> 1 | P37: =AVERAGE('OAI Agentic NHQ'!F:F) -> 2.2384615 | Q37: =MAX('OAI Agentic NHQ'!F:F) -> 4 | R37: =_xlfn.STDEV.S('OAI Agentic NHQ'!F2:F131) -> 1.1398616
B38: Clarity | C38: =MIN('OAI Agentic G+E'!G:G) -> 2 | D38: =AVERAGE('OAI Agentic G+E'!G:G) -> 4.04 | E38: =MAX('OAI Agentic G+E'!G:G) -> 5 | F38: =_xlfn.STDEV.S('OAI RAG G+E'!G2:G26) -> 0.50662281 | H38: Clarity | I38: =MIN('OAI Agentic IT-G'!G:G) -> 2 | J38: =AVERAGE('OAI Agentic IT-G'!G:G) -> 3.96 | K38: =MAX('OAI Agentic IT-G'!G:G) -> 5 | L38: =_xlfn.STDEV.S('OAI RAG IT-G'!G2:G26) -> 0.5 | N38: Clarity | O38: =MIN('OAI Agentic NHQ'!G:G) -> 2 | P38: =AVERAGE('OAI Agentic NHQ'!G:G) -> 3.4923077 | Q38: =MAX('OAI Agentic NHQ'!G:G) -> 5 | R38: =_xlfn.STDEV.S('OAI Agentic NHQ'!G2:G131) -> 0.88261551
B39: Citation Q. | C39: =MIN('OAI Agentic G+E'!H:H) -> 1 | D39: =AVERAGE('OAI Agentic G+E'!H:H) -> 2.28 | E39: =MAX('OAI Agentic G+E'!H:H) -> 3 | F39: =_xlfn.STDEV.S('OAI RAG G+E'!H2:H26) -> 0.62716292 | H39: Citation Q. | I39: =MIN('OAI Agentic IT-G'!H:H) -> 1 | J39: =AVERAGE('OAI Agentic IT-G'!H:H) -> 1.92 | K39: =MAX('OAI Agentic IT-G'!H:H) -> 3 | L39: =_xlfn.STDEV.S('OAI RAG IT-G'!H2:H26) -> 0.64549722 | N39: Citation Q. | O39: =MIN('OAI Agentic NHQ'!H:H) -> 1 | P39: =AVERAGE('OAI Agentic NHQ'!H:H) -> 1.5615385 | Q39: =MAX('OAI Agentic NHQ'!H:H) -> 3 | R39: =_xlfn.STDEV.S('OAI Agentic NHQ'!H2:H131) -> 0.63494914
B40: Overall Score | C40: =MIN('OAI Agentic G+E'!J:J) -> 6 | D40: =AVERAGE('OAI Agentic G+E'!J:J) -> 17.72 | E40: =MAX('OAI Agentic G+E'!J:J) -> 22 | F40: =_xlfn.STDEV.S('OAI RAG G+E'!J2:J26) -> 2.0792627 | H40: Overall Score | I40: =MIN('OAI Agentic IT-G'!J:J) -> 6 | J40: =AVERAGE('OAI Agentic IT-G'!J:J) -> 16.2 | K40: =MAX('OAI Agentic IT-G'!J:J) -> 20 | L40: =_xlfn.STDEV.S('OAI RAG IT-G'!J2:J26) -> 2.2420229 | N40: Overall Score | O40: =MIN('OAI Agentic NHQ'!J:J) -> 6 | P40: =AVERAGE('OAI Agentic NHQ'!J:J) -> 12.869231 | Q40: =MAX('OAI Agentic NHQ'!J:J) -> 22 | R40: =_xlfn.STDEV.S('OAI Agentic NHQ'!J2:J131) -> 5.0538012
B42: Gifts & Entertainment: Gemini Agentic Performance | H42: IT-Governance: OpenAI Agentic Performance | N42: New HQ: OpenAI Agentic Performance
B43: Metric | C43: Min | D43: AVG | E43: Max | F43: StdDev | H43: Metric | I43: Min | J43: AVG | K43: Max | L43: StdDev | N43: Metric | O43: Min | P43: AVG | Q43: Max | R43: StdDev
B44: Factual Acc | C44: =MIN('Gemini Agentic G+E'!D:D) -> 1 | D44: =AVERAGE('Gemini Agentic G+E'!D:D) -> 3.84 | E44: =MAX('Gemini Agentic G+E'!D:D) -> 5 | F44: =_xlfn.STDEV.S('Gemini RAG G+E'!D2:D26) -> 0.50990195 | H44: Factual Acc | I44: =MIN('Gemini Agentic IT-G'!D:D) -> 1 | J44: =AVERAGE('Gemini Agentic IT-G'!D:D) -> 3.6 | K44: =MAX('Gemini Agentic IT-G'!D:D) -> 5 | L44: =_xlfn.STDEV.S('Gemini RAG IT-G'!D2:D26) -> 0.70710678 | N44: Factual Acc | O44: =MIN('Gemini Agentic NHQ'!D:D) -> 1 | P44: =AVERAGE('Gemini Agentic NHQ'!D:D) -> 3.9615385 | Q44: =MAX('Gemini Agentic NHQ'!D:D) -> 5 | R44: =_xlfn.STDEV.S('Gemini Agentic NHQ'!D2:D131) -> 1.088373
B45: Relevance | C45: =MIN('Gemini Agentic G+E'!E:E) -> 1 | D45: =AVERAGE('Gemini Agentic G+E'!E:E) -> 4.56 | E45: =MAX('Gemini Agentic G+E'!E:E) -> 5 | F45: =_xlfn.STDEV.S('Gemini RAG G+E'!E2:E26) -> 0.2 | H45: Relevance | I45: =MIN('Gemini Agentic IT-G'!E:E) -> 1 | J45: =AVERAGE('Gemini Agentic IT-G'!E:E) -> 4.2 | K45: =MAX('Gemini Agentic IT-G'!E:E) -> 5 | L45: =_xlfn.STDEV.S('Gemini RAG IT-G'!E2:E26) -> 0.84261498 | N45: Relevance | O45: =MIN('Gemini Agentic NHQ'!E:E) -> 1 | P45: =AVERAGE('Gemini Agentic NHQ'!E:E) -> 4.2384615 | Q45: =MAX('Gemini Agentic NHQ'!E:E) -> 5 | R45: =_xlfn.STDEV.S('Gemini Agentic NHQ'!E2:E131) -> 1.1398616
B46: Completeness | C46: =MIN('Gemini Agentic G+E'!F:F) -> 1 | D46: =AVERAGE('Gemini Agentic G+E'!F:F) -> 3.4 | E46: =MAX('Gemini Agentic G+E'!F:F) -> 5 | F46: =_xlfn.STDEV.S('Gemini RAG G+E'!F2:F26) -> 0.5 | H46: Completeness | I46: =MIN('Gemini Agentic IT-G'!F:F) -> 1 | J46: =AVERAGE('Gemini Agentic IT-G'!F:F) -> 3 | K46: =MAX('Gemini Agentic IT-G'!F:F) -> 4 | L46: =_xlfn.STDEV.S('Gemini RAG IT-G'!F2:F26) -> 0.83066239 | N46: Completeness | O46: =MIN('Gemini Agentic NHQ'!F:F) -> 1 | P46: =AVERAGE('Gemini Agentic NHQ'!F:F) -> 3.4846154 | Q46: =MAX('Gemini Agentic NHQ'!F:F) -> 5 | R46: =_xlfn.STDEV.S('Gemini Agentic NHQ'!F2:F131) -> 1.393421
...

Sheet Sheet1
A1: OpenAI Raw_Total | B1: Gemini Raw_Total | C1: Mean | D1: Diff | E1: Abs Diff
A2: 20 | B2: 21 | C2: =(A2/B2)/2 -> 0.47619048 | D2: =A2-B2 -> -1 | E2: =ABS(A2-B2) -> 1 | L2: Summary:
A3: 24 | B3: 21 | C3: =(A3/B3)/2 -> 0.57142857 | D3: =A3-B3 -> 3 | E3: =ABS(A3-B3) -> 3 | L3: Bland‑Altman summary stats
A4: 24 | B4: 22 | C4: =(A4/B4)/2 -> 0.54545455 | D4: =A4-B4 -> 2 | E4: =ABS(A4-B4) -> 2 | L4: Mean_of_diffs | M4: =AVERAGE(C:C) -> 0.59720575
A5: 23 | B5: 18 | C5: =(A5/B5)/2 -> 0.63888889 | D5: =A5-B5 -> 5 | E5: =ABS(A5-B5) -> 5 | L5: SD_of_diffs | M5: =_xlfn.STDEV.S(C:C) -> 0.36633186
A6: 20 | B6: 23 | C6: =(A6/B6)/2 -> 0.43478261 | D6: =A6-B6 -> -3 | E6: =ABS(A6-B6) -> 3 | L6: Upper_Limit | M6: =M4 + 1.96*M5 -> 1.3152162
A7: 24 | B7: 23 | C7: =(A7/B7)/2 -> 0.52173913 | D7: =A7-B7 -> 1 | E7: =ABS(A7-B7) -> 1 | L7: Lower_Limit | M7: =M4 - 1.96*M5 -> -0.1208047
A8: 24 | B8: 18 | C8: =(A8/B8)/2 -> 0.66666667 | D8: =A8-B8 -> 6 | E8: =ABS(A8-B8) -> 6 | L8: ±1‑point agreement & exact agreement
A9: 20 | B9: 18 | C9: =(A9/B9)/2 -> 0.55555556 | D9: =A9-B9 -> 2 | E9: =ABS(A9-B9) -> 2 | L9: Exact_Agreement | M9: {=SUMPRODUCT((A2:A1000=B2:B1000)*1)/COUNT(A2:A1000)} -> 0.408
A10: 24 | B10: 18 | C10: =(A10/B10)/2 -> 0.66666667 | D10: =A10-B10 -> 6 | E10: =ABS(A10-B10) -> 6 | L10: Within_1pt | M10: {=SUMPRODUCT((ABS(A2:A1000-B2:B1000)<=1)*1)/COUNT(A2:A1000)} -> 0.58266667
A11: 20 | B11: 19 | C11: =(A11/B11)/2 -> 0.52631579 | D11: =A11-B11 -> 1 | E11: =ABS(A11-B11) -> 1
A12: 20 | B12: 21 | C12: =(A12/B12)/2 -> 0.47619048 | D12: =A12-B12 -> -1 | E12: =ABS(A12-B12) -> 1
A13: 20 | B13: 20 | C13: =(A13/B13)/2 -> 0.5 | D13: =A13-B13 -> 0 | E13: =ABS(A13-B13) -> 0
A14: 23 | B14: 22 | C14: =(A14/B14)/2 -> 0.52272727 | D14: =A14-B14 -> 1 | E14: =ABS(A14-B14) -> 1
A15: 20 | B15: 18 | C15: =(A15/B15)/2 -> 0.55555556 | D15: =A15-B15 -> 2 | E15: =ABS(A15-B15) -> 2
A16: 20 | B16: 18 | C16: =(A16/B16)/2 -> 0.55555556 | D16: =A16-B16 -> 2 | E16: =ABS(A16-B16) -> 2
A17: 24 | B17: 21 | C17: =(A17/B17)/2 -> 0.57142857 | D17: =A17-B17 -> 3 | E17: =ABS(A17-B17) -> 3
A18: 23 | B18: 22 | C18: =(A18/B18)/2 -> 0.52272727 | D18: =A18-B18 -> 1 | E18: =ABS(A18-B18) -> 1
A19: 20 | B19: 23 | C19: =(A19/B19)/2 -> 0.43478261 | D19: =A19-B19 -> -3 | E19: =ABS(A19-B19) -> 3
A20: 20 | B20: 22 | C20: =(A20/B20)/2 -> 0.45454545 | D20: =A20-B20 -> -2 | E20: =ABS(A20-B20) -> 2
A21: 20 | B21: 17 | C21: =(A21/B21)/2 -> 0.58823529 | D21: =A21-B21 -> 3 | E21: =ABS(A21-B21) -> 3
A22: 21 | B22: 20 | C22: =(A22/B22)/2 -> 0.525 | D22: =A22-B22 -> 1 | E22: =ABS(A22-B22) -> 1
... A751: 13 | B751: 21 | C751: =(A751/B751)/2 -> 0.30952381 | D751: =A751-B751 -> -8 | E751: =ABS(A751-B751) -> 8

Sheet Sheet2
B3: Type | C3: Values
B4: Gemini | C4: Gemini | D4: OpenAI | E4: OpenAI
A5: System_Type | B5: Average of Raw_Total2 | C5: Average of Weighted_Total | D5: Average of Raw_Total2 | E5: Average of Weighted_Total
A6: agentic | B6: 18.527778 | C6: 3.9081111 | D6: 14.005556 | E6: 2.9113194
A7: rag | B7: 18.860915 | C7: 3.8561444 | D7: 20.473684 | E7: 4.2110307

Sheet RAW
A1: Question ID | B1: Question | C1: OpenAI Answer | D1: OpenAI System_Type | E1: OpenAI Factual_Accuracy | F1: OpenAI Relevance | G1: OpenAI Completeness | H1: OpenAI Clarity | I1: OpenAI Citation_Quality | J1: OpenAI Weighted_Total | K1: OpenAI Raw_Total | L1: OpenAI Snippet_Grounding_Score | M1: OpenAI Snippet_Count | N1: OpenAI Overall_Assessment | O1: OpenAI Fallback_Used | P1: OpenAI Fallback_Merge_Applied | Q1: OpenAI Original_Internal_Answer_Length | R1: OpenAI Web_Fallback_Length | S1: Gemini Answer | T1: Gemini System_Type | U1: Gemini Factual_Accuracy | V1: Gemini Relevance | W1: Gemini Completeness | X1: Gemini Clarity | Y1: Gemini Citation_Quality | Z1: Gemini Weighted_Total | AA1: Gemini Raw_Total | AB1: Gemini Snippet_Grounding_Score | AC1: Gemini Snippet_Count | AD1: Gemini Overall_Assessment | AE1: Gemini Fallback_Used | AF1: Gemini Fallback_Merge_Applied | AG1: Gemini Original_Internal_Answer_Length | AH1: Gemini Web_Fallback_Length
A2: 1 | B2: Am I allowed to accept a gift from a client worth €15? | C2: In principle, you are not allowed to accept gifts from clients. However, gifts to or from clients of up to EUR 20 (gross) are permissible, provided the client is not a public official. Accepting gifts in the form of cash or cash equivalents is prohibited. Gifts with a gross value of more than EUR 20 from a client to employees must be declined in principle. If declining a gift is not possible, it may be permissible if no "K.O." criteria exist, negative indicators do not outweigh positive ones, and recommendations are followed. A gift is defined as the voluntary transfer of ownership without requiring consideration. Examples include wine, books, and theater tickets. If you accept a gift over EUR 20, you should inform the giver that you should not receive gifts in the future. Analysts may not accept any gifts, including low-value ones, from issuers. The acceptance of cash or cash equivalent gifts is never permitted. Research Analysts and Corporate Finance employees are never permitted to receive gifts. If the gift is over EUR 250 (gross), the bank does not consider it usual and appropriate. If refusing a gift may cause significant offense or embarrassment, the gift may be accepted but should be donated to a charity or put to another use in the Bank's interests, in consultation with AFC Compliance. If you accept a gift, you must notify your line manager. Cases of doubt must always be agreed with AFC Compliance in advance. The acceptance of gifts from customers up to EUR 20 (gross) is always permitted (exception: public officials). For employees taxable in Germany, gifts must be reported to AFC Compliance to assess acceptability and forwarded to Human Resources to check taxation as a non-cash benefit. For employees taxable outside of Germany, AFC Compliance London and Human Resources London must be notified to check for tax deductions. | D2: rag | E2: 4 | F2: 5 | G2: 4 | H2: 4 | I2: 3 | J2: 4.1625 | K2: 20 | L2: 0.29402336 | M2: 6 | N2: The AI response effectively addresses the user's query about accepting a gift worth €15, providing relevant and mostly accurate information. While it demonstrates a good understanding of the guidelines, it could benefit from more explicit references to the snippets and a more comprehensive coverage of compliance requirements for higher-value gifts. Overall, it meets high academic standards but has room for improvement in citation quality and completeness. | O2: FALSE | S2: =VLOOKUP($B2,'Gemini RAW'!$A:$Q,2,FALSE) -> In principle, you are not allowed to accept gifts from clients. However, gifts to or from clients of up to EUR 20 (gross) are permissible, provided the client is not a public official. Accepting gifts in the form of cash or cash equivalents is prohibited. Gifts with a gross value of more than EUR 20 from a client to employees must be declined in principle. If declining a gift is not possible, it may be permissible if no "K.O." criteria exist, negative indicators do not outweigh positive ones, and recommendations are followed. A gift is defined as the voluntary transfer of ownership without requiring consideration. Examples include wine, books, and theater tickets. If you accept a gift over EUR 20, you should inform the giver that you should not receive gifts in the future. Analysts may not accept any gifts, including low-value ones, from issuers. The acceptance of cash or cash equivalent gifts is never permitted. Research Analysts and Corporate Finance employees are never permitted to receive gifts. If the gift is over EUR 250 (gross), the bank does not consider it usual and appropriate. If refusing a gift may cause significant offense or embarrassment, the gift may be accepted but should be donated to a charity or put to another use in the Bank's interests, in consultation with AFC Compliance. If you accept a gift, you must notify your line manager. Cases of doubt must always be agreed with AFC Compliance in advance. The acceptance of gifts from customers up to EUR 20 (gross) is always permitted (exception: public officials). For employees taxable in Germany, gifts must be reported to AFC Compliance to assess acceptability and forwarded to Human Resources to check taxation as a non-cash benefit. For employees taxable outside of Germany, AFC Compliance London and Human Resources London must be notified to check for tax deductions. | T2: =VLOOKUP($B2,'Gemini RAW'!$A:$Q,3,FALSE) -> rag | U2: =VLOOKUP($B2,'Gemini RAW'!$A:$Q,4,FALSE) -> 5 | V2: =VLOOKUP($B2,'Gemini RAW'!$A:$Q,5,FALSE) -> 5 | W2: =VLOOKUP($B2,'Gemini RAW'!$A:$Q,6,FALSE) -> 5 | X2: =VLOOKUP($B2,'Gemini RAW'!$A:$Q,7,FALSE) -> 5 | Y2: =VLOOKUP($B2,'Gemini RAW'!$A:$Q,8,FALSE) -> 1 | Z2: =VLOOKUP($B2,'Gemini RAW'!$A:$Q,9,FALSE) -> 3.64 | AA2: =VLOOKUP($B2,'Gemini RAW'!$A:$Q,10,FALSE) -> 21 | AB2: =VLOOKUP($B2,'Gemini RAW'!$A:$Q,11,FALSE) -> 0.29402336 | AC2: =VLOOKUP($B2,'Gemini RAW'!$A:$Q,12,FALSE) -> 6 | AD2: =VLOOKUP($B2,'Gemini RAW'!$A:$Q,13,FALSE) -> The response provides a factually accurate, relevant, complete, and clear answer to the user's query. However, it lacks proper citations and does not address GDPR compliance, EU AI Act alignment, or audit trail quality. The content quality is excellent, but the source utilization and citation mechanics are poor. | AE2: =VLOOKUP($B2,'Gemini RAW'!$A:$Q,14,FALSE) -> FALSE | AF2: =VLOOKUP($B2,'Gemini RAW'!$A:$Q,15,FALSE) -> 0 | AG2: =VLOOKUP($B2,'Gemini RAW'!$A:$Q,16,FALSE) -> 0 | AH2: =VLOOKUP($B2,'Gemini RAW'!$A:$Q,17,FALSE) -> 0
A3: 2 | B3: Can I give a gift to a client worth €20 exactly? | C3: You are allowed to give a gift to a client worth up to EUR 20 (gross) or equivalent, provided the client is not a public official. Gifts in the form of cash or cash equivalents, such as vouchers for cash payment, are prohibited in all cases and without exception. A gift is defined as the voluntary transfer of ownership, e.g., of an item or a right, without requiring consideration. Examples of gifts include wine, books, and theater tickets. The bank also gives gifts such as wine, calendars, and promotional items like pens and golf balls. Vouchers that cannot be redeemed for cash, such as those for a perfumery, bookstore, or restaurant, are treated as gifts. If you are an employee taxable outside Germany and accept a gift exceeding EUR 20 (gross) in connection with your work for the Bank, you must notify Compliance London and Human Resources London by e-mail. This notification should include the name and address of the company/person from whom the gift originated, a description of the gift and its value, and your name. This is so Human Resources can check if a tax deduction is required. Employees must refuse all gifts received in connection with their work for the Bank whose value exceeds EUR 20 (gross). If refusal is not possible for reasons of politeness, employees taxable in Germany must report all gifts received whose value exceeds EUR 20 (gross). This should be done without delay using the form “Notification to AFC Compliance and Human Resources regarding the acceptance of taxable benefits in kind (gifts exceeding EUR 20 (gross) or equivalent) by an employee”. The form is submitted to AFC Compliance, who will assess whether the gift can be accepted or rejected, inform the employee, and then forward the form to Human Resources. If you give or expect to receive a gift, you should inform the person that all Berenberg Group employees are subject to highly restrictive regulations. Gifts may only be given or accepted under very specific, narrowly defined conditions. The Bank does not consider gifts of more than EUR 250 (gross) to be usual and appropriate. If refusing a gift may cause significant offense or embarrassment, the gift may be accepted but should be donated to a charity of the Bank's choosing or put to another use in the Bank's interests, in consultation with AFC Compliance. If you accept a gift, you must notify your line manager appropriately. Cases of doubt must always be agreed with AFC Compliance in advance but in any case without delay. | D3: rag | E3: 5 | F3: 5 | G3: 5 | H3: 5 | I3: 4 | J3: 4.9125 | K3: 24 | L3: 0.26204663 | M3: 7 | N3: The AI response is highly accurate, relevant, complete, and clear, effectively addressing the user's query about gift-giving limits. While it lacks explicit citations, the grounding in the provided snippets is strong, justifying a high score in citation quality despite the absence of direct references. | O3: FALSE | S3: =VLOOKUP($B3,'Gemini RAW'!$A:$Q,2,FALSE) -> You are allowed to give a gift to a client worth up to EUR 20 (gross) or equivalent, provided the client is not a public official. Gifts in the form of cash or cash equivalents, such as vouchers for cash payment, are prohibited in all cases and without exception. A gift is defined as the voluntary transfer of ownership, e.g., of an item or a right, without requiring consideration. Examples of gifts include wine, books, and theater tickets. The bank also gives gifts such as wine, calendars, and promotional items like pens and golf balls. Vouchers that cannot be redeemed for cash, such as those for a perfumery, bookstore, or restaurant, are treated as gifts. If you are an employee taxable outside Germany and accept a gift exceeding EUR 20 (gross) in connection with your work for the Bank, you must notify Compliance London and Human Resources London by e-mail. This notification should include the name and address of the company/person from whom the gift originated, a description of the gift and its value, and your name. This is so Human Resources can check if a tax deduction is required. Employees must refuse all gifts received in connection with their work for the Bank whose value exceeds EUR 20 (gross). If refusal is not possible for reasons of politeness, employees taxable in Germany must report all gifts received whose value exceeds EUR 20 (gross). This should be done without delay using the form “Notification to AFC Compliance and Human Resources regarding the acceptance of taxable benefits in kind (gifts exceeding EUR 20 (gross) or equivalent) by an employee”. The form is submitted to AFC Compliance, who will assess whether the gift can be accepted or rejected, inform the employee, and then forward the form to Human Resources. If you give or expect to receive a gift, you should inform the person that all Berenberg Group employees are subject to highly restrictive regulations. Gifts may only be given or accepted under very specific, narrowly defined conditions. The Bank does not consider gifts of more than EUR 250 (gross) to be usual and appropriate. If refusing a gift may cause significant offense or embarrassment, the gift may be accepted but should be donated to a charity of the Bank's choosing or put to another use in the Bank's interests, in consultation with AFC Compliance. If you accept a gift, you must notify your line manager appropriately. Cases of doubt must always be agreed with AFC Compliance in advance but in any case without delay. | T3: =VLOOKUP($B3,'Gemini RAW'!$A:$Q,3,FALSE) -> rag | U3: =VLOOKUP($B3,'Gemini RAW'!$A:$Q,4,FALSE) -> 5 | V3: =VLOOKUP($B3,'Gemini RAW'!$A:$Q,5,FALSE) -> 5 | W3: =VLOOKUP($B3,'Gemini RAW'!$A:$Q,6,FALSE) -> 5 | X3: =VLOOKUP($B3,'Gemini RAW'!$A:$Q,7,FALSE) -> 5 | Y3: =VLOOKUP($B3,'Gemini RAW'!$A:$Q,8,FALSE) -> 1 | Z3: =VLOOKUP($B3,'Gemini RAW'!$A:$Q,9,FALSE) -> 4.48 | AA3: =VLOOKUP($B3,'Gemini RAW'!$A:$Q,10,FALSE) -> 21 | AB3: =VLOOKUP($B3,'Gemini RAW'!$A:$Q,11,FALSE) -> 0.26204663 | AC3: =VLOOKUP($B3,'Gemini RAW'!$A:$Q,12,FALSE) -> 7 | AD3: =VLOOKUP($B3,'Gemini RAW'!$A:$Q,13,FALSE) -> The response is excellent in terms of content quality, providing accurate, relevant, complete, and clear information about gift-giving policies. However, it lacks proper citation and audit trail information, which significantly reduces its academic rigor. The response effectively answers the user's question but fails to provide transparency regarding its sources. | AE3: =VLOOKUP($B3,'Gemini RAW'!$A:$Q,14,FALSE) -> FALSE | AF3: =VLOOKUP($B3,'Gemini RAW'!$A:$Q,15,FALSE) -> 0 | AG3: =VLOOKUP($B3,'Gemini RAW'!$A:$Q,16,FALSE) -> 0 | AH3: =VLOOKUP($B3,'Gemini RAW'!$A:$Q,17,FALSE) -> 0
A4: 3 | B4: What should I do if I receive a gift worth €30 from a business partner? | C4: If you receive a gift worth €30 from a business partner, here's what you should do, based on Berenberg's guidelines: * **General Rule:** In principle, gifts with a gross value of more than EUR 20 from a (potential) client/business partner to employees must be declined. * **Declining the Gift:** You should take a tactful approach in each specific case. * **If Refusal is Not Possible:** If a refusal is not possible, for reasons of politeness, the following applies: * **Employees taxable in Germany:** Report the gift using the form “Notification to AFC Compliance and Human Resources regarding the acceptance of taxable benefits in kind (gifts exceeding EUR 20 (gross) or equivalent) by an employee” (Appendix 2). Complete and submit this form to AFC Compliance. AFC Compliance will assess whether the gift can be accepted or should be rejected, informs the employee accordingly, and then forwards the form to the Human Resources department. * **Employees taxable outside Germany (especially in the UK):** Notify Compliance London and Human Resources London by e-mail. Include the name and address of the company/person from whom the gift originated, a description of the gift and its value (plausible estimate), and your name. This allows Human Resources to check the extent to which a tax deduction is required. * **Additional Steps:** * Give feedback to the gift giver that they should refrain from giving gifts in the future. * Notify your line manager appropriately if you accept the gift. * **Important Considerations:** * The acceptance of cash or cash equivalents, such as vouchers for cash payment, is prohibited in all cases and without exception. * If you are in any doubt as to whether you can accept a gift, consult with AFC Compliance. * If you believe that any bribery, corruption or other breach of policy has occurred or may occur, you must refuse it and report it immediately to your manager and AFC Compliance. * **Gifts to family members:** Gifts offered to family members, relatives or close associates of Berenberg employees may not be accepted. * **Gifts during bidding process:** During the bidding or pitch process for a new transaction, business mandate, product, service or relationship the receipt of gifts (of any value) is strictly prohibited. | D4: rag | E4: 5 | F4: 5 | G4: 5 | H4: 5 | I4: 4 | J4: 4.9125 | K4: 24 | L4: 0.4411629 | M4: 6 | N4: The AI response is exemplary in addressing the user's query with high factual accuracy, relevance, completeness, and clarity. It effectively synthesizes information from the snippets, although it lacks explicit citations which would enhance citation quality. Overall, it meets and exceeds academic standards. | O4: FALSE | S4: =VLOOKUP($B4,'Gemini RAW'!$A:$Q,2,FALSE) -> If you receive a gift worth €30 from a business partner, here's what you should do, based on Berenberg's guidelines: * **General Rule:** In principle, gifts with a gross value of more than EUR 20 from a (potential) client/business partner to employees must be declined. * **Declining the Gift:** You should take a tactful approach in each specific case. * **If Refusal is Not Possible:** If a refusal is not possible, for reasons of politeness, the following applies: * **Employees taxable in Germany:** Report the gift using the form “Notification to AFC Compliance and Human Resources regarding the acceptance of taxable benefits in kind (gifts exceeding EUR 20 (gross) or equivalent) by an employee” (Appendix 2). Complete and submit this form to AFC Compliance. AFC Compliance will assess whether the gift can be accepted or should be rejected, informs the employee accordingly, and then forwards the form to the Human Resources department. * **Employees taxable outside Germany (especially in the UK):** Notify Compliance London and Human Resources London by e-mail. Include the name and address of the company/person from whom the gift originated, a description of the gift and its value (plausible estimate), and your name. This allows Human Resources to check the extent to which a tax deduction is required. * **Additional Steps:** * Give feedback to the gift giver that they should refrain from giving gifts in the future. * Notify your line manager appropriately if you accept the gift. * **Important Considerations:** * The acceptance of cash or cash equivalents, such as vouchers for cash payment, is prohibited in all cases and without exception. * If you are in any doubt as to whether you can accept a gift, consult with AFC Compliance. * If you believe that any bribery, corruption or other breach of policy has occurred or may occur, you must refuse it and report it immediately to your manager and AFC Compliance. * **Gifts to family members:** Gifts offered to family members, relatives or close associates of Berenberg employees may not be accepted. * **Gifts during bidding process:** During the bidding or pitch process for a new transaction, business mandate, product, service or relationship the receipt of gifts (of any value) is strictly prohibited. | T4: =VLOOKUP($B4,'Gemini RAW'!$A:$Q,3,FALSE) -> rag | U4: =VLOOKUP($B4,'Gemini RAW'!$A:$Q,4,FALSE) -> 4 | V4: =VLOOKUP($B4,'Gemini RAW'!$A:$Q,5,FALSE) -> 5 | W4: =VLOOKUP($B4,'Gemini RAW'!$A:$Q,6,FALSE) -> 4 | X4: =VLOOKUP($B4,'Gemini RAW'!$A:$Q,7,FALSE) -> 5 | Y4: =VLOOKUP($B4,'Gemini RAW'!$A:$Q,8,FALSE) -> 4 | Z4: =VLOOKUP($B4,'Gemini RAW'!$A:$Q,9,FALSE) -> 3.46 | AA4: =VLOOKUP($B4,'Gemini RAW'!$A:$Q,10,FALSE) -> 22 | AB4: =VLOOKUP($B4,'Gemini RAW'!$A:$Q,11,FALSE) -> 0.4411629 | AC4: =VLOOKUP($B4,'Gemini RAW'!$A:$Q,12,FALSE) -> 6 | AD4: =VLOOKUP($B4,'Gemini RAW'!$A:$Q,13,FALSE) -> The response provides a relevant and clear answer to the user's query, offering practical advice based on Berenberg's guidelines. The content is generally accurate and comprehensive, although it could benefit from acknowledging the specific context of the guidelines. The citation quality is acceptable but could be improved with a more explicit reference. The response completely fails to address GDPR, EU AI Act, and audit trail considerations. | AE4: =VLOOKUP($B4,'Gemini RAW'!$A:$Q,14,FALSE) -> FALSE | AF4: =VLOOKUP($B4,'Gemini RAW'!$A:$Q,15,FALSE) -> 0 | AG4: =VLOOKUP($B4,'Gemini RAW'!$A:$Q,16,FALSE) -> 0 | AH4: =VLOOKUP($B4,'Gemini RAW'!$A:$Q,17,FALSE) -> 0
A5: 4 | B5: Are cash or gift vouchers ever acceptable as gifts? | C5: The acceptance of cash or cash equivalent gifts, such as gift certificates or vouchers, is never permitted. This prohibition is without exception. Vouchers that do not allow for cash payment are treated as gifts. In principle, you are not allowed to accept gifts from or give gifts to clients. However, this does not include gifts to or from clients of up to EUR 20 (gross) or equivalent, provided the client is not a public official. Gifts with a gross value of more than EUR 20 from a (potential) client/business partner to employees must be declined. Gifts offered to family members, relatives or close associates of Berenberg employees may not be accepted. | D5: rag | E5: 5 | F5: 5 | G5: 4 | H5: 5 | I5: 4 | J5: 4.725 | K5: 23 | L5: 0.46329244 | M5: 4 | N5: The AI response effectively addresses the user query with high factual accuracy and relevance. It is clear and well-structured, though it could improve in completeness by elaborating on the exceptions to the rules regarding gift acceptance. The lack of explicit citations does not detract significantly from the response, but clearer attribution would enhance citation quality. | O5: FALSE | S5: =VLOOKUP($B5,'Gemini RAW'!$A:$Q,2,FALSE) -> The acceptance of cash or cash equivalent gifts, such as gift certificates or vouchers, is never permitted. This prohibition is without exception. Vouchers that do not allow for cash payment are treated as gifts. In principle, you are not allowed to accept gifts from or give gifts to clients. However, this does not include gifts to or from clients of up to EUR 20 (gross) or equivalent, provided the client is not a public official. Gifts with a gross value of more than EUR 20 from a (potential) client/business partner to employees must be declined. Gifts offered to family members, relatives or close associates of Berenberg employees may not be accepted. | T5: =VLOOKUP($B5,'Gemini RAW'!$A:$Q,3,FALSE) -> rag | U5: =VLOOKUP($B5,'Gemini RAW'!$A:$Q,4,FALSE) -> 4 | V5: =VLOOKUP($B5,'Gemini RAW'!$A:$Q,5,FALSE) -> 5 | W5: =VLOOKUP($B5,'Gemini RAW'!$A:$Q,6,FALSE) -> 4 | X5: =VLOOKUP($B5,'Gemini RAW'!$A:$Q,7,FALSE) -> 4 | Y5: =VLOOKUP($B5,'Gemini RAW'!$A:$Q,8,FALSE) -> 1 | Z5: =VLOOKUP($B5,'Gemini RAW'!$A:$Q,9,FALSE) -> 3.16 | AA5: =VLOOKUP($B5,'Gemini RAW'!$A:$Q,10,FALSE) -> 18 | AB5: =VLOOKUP($B5,'Gemini RAW'!$A:$Q,11,FALSE) -> 0.46329244 | AC5: =VLOOKUP($B5,'Gemini RAW'!$A:$Q,12,FALSE) -> 4 | AD5: =VLOOKUP($B5,'Gemini RAW'!$A:$Q,13,FALSE) -> The response is generally good in terms of content quality, providing a relevant and mostly accurate answer to the user's query. However, it lacks citations and does not address GDPR, EU AI Act, or audit trail considerations. The response is also specific to Berenberg employees, which limits its general applicability. | AE5: =VLOOKUP($B5,'Gemini RAW'!$A:$Q,14,FALSE) -> FALSE | AF5: =VLOOKUP($B5,'Gemini RAW'!$A:$Q,15,FALSE) -> 0 | AG5: =VLOOKUP($B5,'Gemini RAW'!$A:$Q,16,FALSE) -> 0 | AH5: =VLOOKUP($B5,'Gemini RAW'!$A:$Q,17,FALSE) -> 0
A6: 5 | B6: Can I accept a bottle of wine from a client if it is under €20? | C6: In principle, you are not allowed to accept gifts from clients. However, gifts to or from clients of up to EUR 20 (gross) are permissible, provided the client is not a public official. If a gift exceeds EUR 20 (gross), it should be declined. If declining the gift is not possible, you must report it. For employees taxable in Germany, you must report the gift using form Anlage 2 to AFC Compliance for assessment and forwarding to Human Resources to check taxation as a non-cash benefit. For employees taxable outside of Germany, you must report the gift via email to AFC Compliance London and Human Resources London, including the name and address of the gift giver, description and value of the gift, and your name, to check for tax deductions. If the gift is over 20 EUR (gross), you should inform the giver that you should not receive gifts in the future. Analyst (Research) are not allowed to accept any gifts. Accepting gifts in the form of cash or cash equivalents is prohibited. | D6: rag | E6: 4 | F6: 5 | G6: 4 | H6: 4 | I6: 3 | J6: 4.1625 | K6: 20 | L6: 0.20945005 | M6: 6 | N6: The AI response effectively addresses the user's query with relevant and mostly accurate information regarding gift acceptance policies. While it is clear and well-structured, it could benefit from more explicit grounding in the provided snippets and a more comprehensive coverage of the policy implications for different employee categories. | O6: FALSE | S6: =VLOOKUP($B6,'Gemini RAW'!$A:$Q,2,FALSE) -> In principle, you are not allowed to accept gifts from clients. However, gifts to or from clients of up to EUR 20 (gross) are permissible, provided the client is not a public official. If a gift exceeds EUR 20 (gross), it should be declined. If declining the gift is not possible, you must report it. For employees taxable in Germany, you must report the gift using form Anlage 2 to AFC Compliance for assessment and forwarding to Human Resources to check taxation as a non-cash benefit. For employees taxable outside of Germany, you must report the gift via email to AFC Compliance London and Human Resources London, including the name and address of the gift giver, description and value of the gift, and your name, to check for tax deductions. If the gift is over 20 EUR (gross), you should inform the giver that you should not receive gifts in the future. Analyst (Research) are not allowed to accept any gifts. Accepting gifts in the form of cash or cash equivalents is prohibited. | T6: =VLOOKUP($B6,'Gemini RAW'!$A:$Q,3,FALSE) -> rag | U6: =VLOOKUP($B6,'Gemini RAW'!$A:$Q,4,FALSE) -> 5 | V6: =VLOOKUP($B6,'Gemini RAW'!$A:$Q,5,FALSE) -> 5 | W6: =VLOOKUP($B6,'Gemini RAW'!$A:$Q,6,FALSE) -> 5 | X6: =VLOOKUP($B6,'Gemini RAW'!$A:$Q,7,FALSE) -> 5 | Y6: =VLOOKUP($B6,'Gemini RAW'!$A:$Q,8,FALSE) -> 3 | Z6: =VLOOKUP($B6,'Gemini RAW'!$A:$Q,9,FALSE) -> 4.88 | AA6: =VLOOKUP($B6,'Gemini RAW'!$A:$Q,10,FALSE) -> 23 | AB6: =VLOOKUP($B6,'Gemini RAW'!$A:$Q,11,FALSE) -> 0.20945005 | AC6: =VLOOKUP($B6,'Gemini RAW'!$A:$Q,12,FALSE) -> 6 | AD6: =VLOOKUP($B6,'Gemini RAW'!$A:$Q,13,FALSE) -> The response is excellent in terms of content quality, providing a factually accurate, relevant, complete, and clear answer to the user's query. The source utilization is adequate, as the information is grounded in the provided snippets, but the lack of explicit citations reduces the overall score. The response also demonstrates good compliance with GDPR and the EU AI Act. | AE6: =VLOOKUP($B6,'Gemini RAW'!$A:$Q,14,FALSE) -> FALSE | AF6: =VLOOKUP($B6,'Gemini RAW'!$A:$Q,15,FALSE) -> 0 | AG6: =VLOOKUP($B6,'Gemini RAW'!$A:$Q,16,FALSE) -> 0 | AH6: =VLOOKUP($B6,'Gemini RAW'!$A:$Q,17,FALSE) -> 0
